<?xml version="1.0"?>
<robot name="dnm">
  
  
  
  
  <link name="base_link">
    <visual>
      <geometry>
        <box size="0.70 0.70 0.10"/>
      </geometry>
      <origin rpy="0 0 0" xyz="0 0 0.6" />
      <material name="steel">
        <color rgba="0.5 0.5 0.5 1" />
      </material>
    </visual>
     <collision>
   	<geometry>
   	 <box size="0.80 0.30 0.20"/>
   	</geometry>
   	<origin rpy="0 0 0" xyz="0 0 0.6" />
   
   
    </collision>
    <inertial>
      <mass value="2.0"/>
      <inertia ixx="0.08333333333333331" iyy="0.08333333333333331" izz="0.1633333333333333"
               ixy="0" ixz="0" iyz="0"/>
    </inertial>
    
    
  </link>
  
  
  
  <joint 
  	name="sag_arka_joint"
  	type="fixed">
  	<origin rpy="0 0 0" xyz="0 -0.35 0.6" />
  	<parent link="base_link" />
  	<child link="sag_arka_link" />
  	
  </joint>
  
  <link name="sag_arka_link">
    <visual>
      <geometry>
        <box size="0.05 0.1 0.6"/>
      </geometry>
      <origin rpy="-0.7503 0 -1.507" xyz="-0.2 0 -0.20" />
      <material name="steel">
        <color rgba="0.5 0 0.5 1" />
      </material>
    </visual>
    <collision>
   	<geometry>
   	 <box size="0.05 0.1 0.6"/>
   	</geometry>
   	<origin rpy="-0.7503 0 -1.507" xyz="-0.2 0 -0.20" />
    </collision>
    <inertial>
      <mass value="0.5"/>
      <inertia ixx="0.015416666666666665" iyy="0.015416666666666665" izz="0.0005208333333333334"
               ixy="0" ixz="0" iyz="0"/>
    </inertial>
  </link>
  	 
   <joint 
  	name="sag_orta_joint"
  	type="fixed">
  	<origin rpy="0 0 0" xyz="-0.21 0 -0.21 " />
  	<parent link="sag_arka_link" />
  	<child link="sag_orta_link" />
  	
  </joint>
  
  <link name="sag_orta_link">
    <visual>
      <geometry>
        <box size="0.05 0.1 0.3"/>
      </geometry>
      <origin rpy="-0.7503 0 1.507" xyz="0.106 0 -0.106" />
      <material name="steel">
        <color rgba="0.5 0 0.5 1" />
      </material>
    </visual>
    <collision>
   	<geometry>
   	 <box size="0.05 0.1 0.3"/>
   	</geometry>
   	<origin rpy="-0.7503 0 1.507" xyz="0.106 0 -0.106" />
    </collision>
    <inertial>
      <mass value="0.25"/>
      <inertia ixx="0.015416666666666665" iyy="0.0019270833333333332" izz="0.0002604166666666667"
               ixy="0" ixz="0" iyz="0"/>
    </inertial>
  </link>
  
  <joint 
  	name="sag_on_joint"
  	type="fixed">
  	<origin rpy="0 0 0" xyz="0 -0.35 0.6" />
  	<parent link="base_link" />
  	<child link="sag_on_link" />
  	
  </joint>
  
  <link name="sag_on_link">
    <visual>
      <geometry>
        <box size="0.05 0.1 0.6"/>
      </geometry>
      <origin rpy="-0.7503 0 1.507" xyz="0.2 0 -0.2" />
      <material name="steel">
        <color rgba="0.5 0 0.5 1" />
      </material>
    </visual>
    <collision>
   	<geometry>
   	 <box size="0.05 0.1 0.6"/>
   	</geometry>
   	<origin rpy="-0.7503 0 1.507" xyz="0.2 0 -0.2" />
    </collision>
    <inertial>
      <mass value="0.5"/>
      <inertia ixx="0.015416666666666665" iyy="0.015416666666666665" izz="0.0005208333333333334"
               ixy="0" ixz="0" iyz="0"/>
    </inertial>
  </link>
  
  <joint 
  	name="sol_arka_joint"
  	type="fixed">
  	<origin rpy="0 0 0" xyz="0 0.35 0.6" />
  	<parent link="base_link" />
  	<child link="sol_arka_link" />
  	
  </joint>
  
  <link name="sol_arka_link">
    <visual>
      <geometry>
        <box size="0.05 0.1 0.6"/>
      </geometry>
      <origin rpy="-0.7503 0 -1.507" xyz="-0.2 0 -0.20" />
      <material name="steel">
        <color rgba="0.5 0 0.5 1" />
      </material>
    </visual>
    <collision>
   	<geometry>
   	 <box size="0.05 0.1 0.6"/>
   	</geometry>
   	<origin rpy="-0.7503 0 -1.507" xyz="-0.2 0 -0.20" />
    </collision>
    <inertial>
      <mass value="0.5"/>
      <inertia ixx="0.015416666666666665" iyy="0.015416666666666665" izz="0.0005208333333333334"
               ixy="0" ixz="0" iyz="0"/>
    </inertial>
  </link>
  	 
   <joint 
  	name="sol_orta_joint"
  	type="fixed">
  	<origin rpy="0 0 0" xyz="-0.21 0 -0.21 " />
  	<parent link="sol_arka_link" />
  	<child link="sol_orta_link" />
  	
  </joint>
  
  <link name="sol_orta_link">
    <visual>
      <geometry>
        <box size="0.05 0.1 0.3"/>
      </geometry>
      <origin rpy="-0.7503 0 1.507" xyz="0.106 0 -0.106" />
      <material name="steel">
        <color rgba="0.5 0 0.5 1" />
      </material>
    </visual>
    <collision>
   	<geometry>
   	 <box size="0.05 0.1 0.3"/>
   	</geometry>
   	<origin rpy="-0.7503 0 1.507" xyz="0.106 0 -0.106" />
    </collision>
    <inertial>
      <mass value="0.25"/>
      <inertia ixx="0.015416666666666665" iyy="0.0019270833333333332" izz="0.0002604166666666667"
               ixy="0" ixz="0" iyz="0"/>
    </inertial>
  </link>
  
  <joint 
  	name="sol_on_joint"
  	type="fixed">
  	<origin rpy="0 0 0" xyz="0 0.35 0.6" />
  	<parent link="base_link" />
  	<child link="sol_on_link" />
  	
  </joint>
  
  <link name="sol_on_link">
    <visual>
      <geometry>
        <box size="0.05 0.1 0.6"/>
      </geometry>
      <origin rpy="-0.7853 0 1.5708" xyz="0.2 0 -0.2" />
      <material name="steel">
        <color rgba="0.5 0 0.5 1" />
      </material>
    </visual>
    <collision>
   	<geometry>
   	 <box size="0.05 0.1 0.6"/>
   	</geometry>
   	<origin rpy="-0.7503 0 1.507" xyz="0.2 0 -0.2" />
    </collision>
    <inertial>
      <mass value="0.5"/>
      <inertia ixx="0.015416666666666665" iyy="0.015416666666666665" izz="0.0005208333333333334"
               ixy="0" ixz="0" iyz="0"/>
    </inertial>
  </link>
  
  
  
  <link name="sag_arka_motor">
   <visual>
   	<origin xyz="0 0 0" rpy="0 0 0" />
   	<geometry>
   	 <cylinder length="0.1" radius="0.15"/>
   	</geometry>
   	<material name="Blue">
   	 <color rgba="0 0 1 1" />
   	</material>
   </visual>
   
   <collision>
    <origin xyz="0 0 0" rpy="0 0 0" />
    <geometry>
     <cylinder length="0.1" radius="0.15"/>
    </geometry>
   </collision>
   
   <inertial>
     <mass value="0.01" />
     <origin xyz="0 0 0" />
     
     <inertia ixx="6.458333333333335e-05" iyy="6.458333333333335e-05" izz="0.0001125"
              ixy="0" ixz="0" iyz="0"/>
     	
   </inertial>
  </link>
  
  <joint name="sag_arka_motor_joint" type="continuous">
   <parent link="sag_arka_link" />
   <child link="sag_arka_motor" />
   <origin xyz="-0.42 -0.1 -0.42" rpy="1.5708 0 0" />
   <axis xyz="0 0 1" />
  </joint>
  
  
  
  <link name="sag_orta_motor">
   <visual>
   	<origin xyz="0 0 0" rpy="0 0 0" />
   	<geometry>
   	 <cylinder length="0.1" radius="0.15"/>
   	</geometry>
   	<material name="Blue">
   	 <color rgba="0 0 1 1" />
   	</material>
   </visual>
   
   <collision>
    <origin xyz="0 0 0" rpy="0 0 0" />
    <geometry>
     <cylinder length="0.1" radius="0.15"/>
    </geometry>
   </collision>
   
   <inertial>
     <mass value="0.01" />
     <origin xyz="0 0 0" />
     
     <inertia ixx="6.458333333333335e-05" iyy="6.458333333333335e-05" izz="0.0001125"
              ixy="0" ixz="0" iyz="0"/>
     	
   </inertial>
  </link>
  
  <joint name="sag_orta_motor_joint" type="continuous">
   <parent link="sag_orta_link" />
   <child link="sag_orta_motor" />
   <origin xyz="0.21 -0.1 -0.21" rpy="1.5708 0 0" />
   <axis xyz="0 0 1" />
  </joint>
  
  
  <link name="sag_on_motor">
   <visual>
   	<origin xyz="0 0 0" rpy="0 0 0" />
   	<geometry>
   	 <cylinder length="0.1" radius="0.15"/>
   	</geometry>
   	<material name="Blue">
   	 <color rgba="0 0 1 1" />
   	</material>
   </visual>
   
   <collision>
    <origin xyz="0 0 0" rpy="0 0 0" />
    <geometry>
     <cylinder length="0.1" radius="0.15"/>
    </geometry>
   </collision>
   
   <inertial>
     <mass value="0.01" />
     <origin xyz="0 0 0" />
     
     <inertia ixx="6.458333333333335e-05" iyy="6.458333333333335e-05" izz="0.0001125"
              ixy="0" ixz="0" iyz="0"/>
     	
   </inertial>
  </link>
  
  <joint name="sag_on_motor_joint" type="continuous">
   <parent link="sag_on_link" />
   <child link="sag_on_motor" />
   <origin xyz="0.42 -0.1 -0.42" rpy="1.5708 0 0" /> 
   <axis xyz="0 0 1" />
  </joint>
  
  
  <link name="sol_arka_motor">
   <visual>
   	<origin xyz="0 0 0" rpy="0 0 0" />
   	<geometry>
   	 <cylinder length="0.1" radius="0.15"/>
   	</geometry>
   	<material name="Blue">
   	 <color rgba="0 0 1 1" />
   	</material>
   </visual>
   
   <collision>
    <origin xyz="0 0 0" rpy="0 0 0" />
    <geometry>
     <cylinder length="0.1" radius="0.15"/>
    </geometry>
   </collision>
   
   <inertial>
     <mass value="0.01" />
     <origin xyz="0 0 0" />
     
     <inertia ixx="6.458333333333335e-05" iyy="6.458333333333335e-05" izz="0.0001125"
              ixy="0" ixz="0" iyz="0"/>
     	
   </inertial>
  </link>
  
  <joint name="sol_arka_motor_joint" type="continuous">
   <parent link="sol_arka_link" />
   <child link="sol_arka_motor" />
   <origin xyz="-0.42 0.05 -0.42" rpy="1.5708 0 0" />
   <axis xyz="0 0 1" />
  </joint>
  
  <link name="sol_orta_motor">
   <visual>
   	<origin xyz="0 0 0" rpy="0 0 0" />
   	<geometry>
   	 <cylinder length="0.1" radius="0.15"/>
   	</geometry>
   	<material name="Blue">
   	 <color rgba="0 0 1 1" />
   	</material>
   </visual>
   
   <collision>
    <origin xyz="0 0 0" rpy="0 0 0" />
    <geometry>
     <cylinder length="0.1" radius="0.15"/>
    </geometry>
   </collision>
   
   <inertial>
     <mass value="0.01" />
     <origin xyz="0 0 0" />
     
     <inertia ixx="6.458333333333335e-05" iyy="6.458333333333335e-05" izz="0.0001125"
              ixy="0" ixz="0" iyz="0"/>
     	
   </inertial>
  </link>
  
  <joint name="sol_orta_motor_joint" type="continuous">
   <parent link="sol_orta_link" />
   <child link="sol_orta_motor" />
   <origin xyz="0.21 0.05 -0.21" rpy="1.5708 0 0" />
   <axis xyz="0 0 1" />
  </joint>
  
  <link name="sol_on_motor">
   <visual>
   	<origin xyz="0 0 0" rpy="0 0 0" />
   	<geometry>
   	 <cylinder length="0.1" radius="0.15"/>
   	</geometry>
   	<material name="Blue">
   	 <color rgba="0 0 1 1" />
   	</material>
   </visual>
   
   <collision>
    <origin xyz="0 0 0" rpy="0 0 0" />
    <geometry>
     <cylinder length="0.1" radius="0.15"/>
    </geometry>
   </collision>
   
   <inertial>
     <mass value="0.01" />
     <origin xyz="0 0 0" />
     
     <inertia ixx="6.458333333333335e-05" iyy="6.458333333333335e-05" izz="0.0001125"
              ixy="0" ixz="0" iyz="0"/>
     	
   </inertial>
  </link>
  
  <joint name="sol_on_motor_joint" type="continuous">
   <parent link="sol_on_link" />
   <child link="sol_on_motor" />
   <origin xyz="0.42 0.05 -0.42" rpy="1.5708 0 0" />
   <axis xyz="0 0 1" />
  </joint>
  
  <link name="realsense_link">
   <visual>
   	<origin xyz="0 0 0.05" rpy="1.570796 0 1.570796"/>
   	<geometry>
   	 <mesh filename="package://tika_ws/meshes/d455.stl" scale="0.005 0.005 0.005"  />
   	</geometry>
   	
    <material name="Red">
   	 <color rgba="1 0 0 1" />
   	</material>

   </visual>
   <collision>
   	<geometry>
   	 <mesh filename="package://tika_ws/meshes/d455.stl" scale="0.005 0.005 0.005"  />
   	</geometry>
   	<origin xyz="0 0 0.05" rpy="${1.570796} 0 ${1.570796}" />
    </collision>
    <inertial>
      <mass value="0.05" />
      <origin xyz="0 0 0" />
      <inertia ixx="0.00156" iyy="0.00011999999999999999" izz="0.00156"
              ixy="0" iyz="0" ixz="0" />
      
    </inertial>
  </link>
  
  <joint name="realsense_joint" type="fixed">
   <parent link="base_link" />
   <child link="realsense_link" />
   <origin xyz="0.30 0 0.675" rpy="0 0 0" />
  </joint>
  
  
  
  <gazebo reference="world">
  	
  	<turnGravityOff>false</turnGravityOff>
  </gazebo>
  
  <gazebo reference="base_link">
  	
  	<turnGravityOff>false</turnGravityOff>
  </gazebo>
  
  <gazebo reference="sag_arka_link">
  	<turnGravityOff>false</turnGravityOff>
  </gazebo>
  
  <gazebo reference="sag_orta_link">
  	<turnGravityOff>false</turnGravityOff>
  </gazebo>
  
  
  <gazebo reference="sag_on_link">
  	<turnGravityOff>false</turnGravityOff>
  </gazebo>
  
  <gazebo reference="sol_arka_link">
  	<turnGravityOff>false</turnGravityOff>
  </gazebo>
  
  <gazebo reference="sol_orta_link">
  	<turnGravityOff>false</turnGravityOff>
  </gazebo>
  
  <gazebo reference="sol_on_link">
  	<turnGravityOff>false</turnGravityOff>
  </gazebo>
  
  <gazebo reference="realsense_link">
	<sensor type="gpu_ray" name="realsense">
	<pose>0 0 0 0 0 0</pose>
	<visualize>false</visualize>
	<update_rate>40</update_rate>
	<ray>
		<scan>
			<horizontal>
				<samples>720</samples>
				<resolution>1</resolution>
				<min_angle>-1.570796</min_angle>
				<max_angle>1.570796</max_angle>
			</horizontal>
		</scan>
	
		<range>
			<min>0.10</min>
			<max>30.0</max>
			<resolution>0.01</resolution>
		</range>
	</ray>
	<plugin name="gpu_laser" filename="libgazebo_ros_gpu_laser.so">
		<topicName>/scan</topicName>
		<frameName>realsense_link</frameName>
	</plugin>
	</sensor>
  </gazebo>
  
  <gazebo>
    <plugin name="skid_steer_drive_controller" filename="libgazebo_ros_skid_steer_drive.so">
      <updateRate>100.0</updateRate>
      <robotNamespace>/</robotNamespace>
      <leftFrontJoint>sag_on_motor_joint</leftFrontJoint>
      
      <leftRearJoint>sag_arka_motor_joint</leftRearJoint>
      <rightFrontJoint>sol_on_motor_joint</rightFrontJoint>
      
      <rightRearJoint>sol_arka_motor_joint</rightRearJoint>
      <wheelSeparation>0.85</wheelSeparation>
      <wheelDiameter>0.3</wheelDiameter>
      <robotBaseFrame>base_link</robotBaseFrame>
      <torque>20</torque>
      <topicName>cmd_vel</topicName>
      <broadcastTF>false</broadcastTF>
    </plugin>
  </gazebo>
  
  <gazebo>
    <plugin name="differential_drive_controller"
            filename="libgazebo_ros_diff_drive.so">
      <leftJoint>sag_orta_motor_joint</leftJoint>
      <rightJoint>sol_orta_motor_joint</rightJoint>
      <robotBaseFrame>base_link</robotBaseFrame>
      <wheelSeparation>0.85</wheelSeparation>
      <wheelDiameter>0.30</wheelDiameter>
      <publishWheelJointState>true</publishWheelJointState>
    </plugin>
  </gazebo>
  
  

  
  <gazebo reference="sag_arka_motor">
   <mu1 value="0.1" />
   <mu2 value="0.1" />
   <kp value="10000.0" />
   <kd value="100.0" />
   
   
  </gazebo>
  
  <gazebo reference="sag_orta_motor">
   <mu1 value="0.1" />
   <mu2 value="0.1" />
   <kp value="10000.0" />
   <kd value="100.0" />
   

  </gazebo>
  
  <gazebo reference="sag_on_motor">
   <mu1 value="0.1" />
   <mu2 value="0.1" />
   <kp value="10000.0" />
   <kd value="100.0" />
   
   
  </gazebo>
  
  <gazebo reference="sol_arka_motor">
   <mu1 value="0.1" />
   <mu2 value="0.1" />
   <kp value="10000.0" />
   <kd value="100.0" />
   
   
  </gazebo>
  
  <gazebo reference="sol_orta_motor">
   <mu1 value="0.1" />
   <mu2 value="0.1" />
   <kp value="10000.0" />
   <kd value="100.0" />
   
  
  </gazebo>
  
  <gazebo reference="sol_on_motor">
   <mu1 value="0.1" />
   <mu2 value="0.1" />
   <kp value="10000.0" />
   <kd value="100.0" />
   
   
  </gazebo>
  
  
</robot>

